<?xml version="1.0" encoding="utf-8"?>
<robot name="body_v5">
	<link name="body:1">
		<inertial>
			<mass value="1.497232781741777"/>
			<origin rpy="0 0 0" xyz="-0.00017329149375959154 -9.904215329983418e-05 0.18542155749322675"/>
			<inertia ixx="0.010405816822772078" ixy="-1.1020043490185575e-07" ixz="-1.3394016036604117e-06" iyy="0.010405384331184632" iyz="-3.2607172834594464e-07" izz="0.0037101985806207217"/>
		</inertial>
		<collision name="body:1_collision">
			<origin rpy="0.0 -0.0 0.0" xyz="0.0 0.0 0.0"/>
			<geometry>
				<mesh filename="package://qross2/meshes/body.stl" scale="1.0 1.0 1.0"/>
			</geometry>
		</collision>
		<visual name="body:1_visual">
			<origin rpy="0.0 -0.0 0.0" xyz="0.0 0.0 0.0"/>
			<geometry>
				<mesh filename="package://qross2/meshes/body.stl" scale="1.0 1.0 1.0"/>
			</geometry>
		</visual>
	</link>
	<link name="link1_v2:1">
		<inertial>
			<mass value="0.16654938800905217"/>
			<origin rpy="0 0 0" xyz="0.04567157363562954 0.018319891913309787 -0.008781562884711325"/>
			<inertia ixx="4.581878345515662e-05" ixy="1.0402405561863775e-06" ixz="-5.775774582001603e-06" iyy="8.84112742834489e-05" iyz="-2.5963754507403873e-07" izz="8.007801444305187e-05"/>
		</inertial>
		<collision name="link1_v2:1_collision">
			<origin rpy="0.0 -0.0 0.0" xyz="-0.058249999999999955 0.01804999999999988 -0.18500000000000014"/>
			<geometry>
				<mesh filename="package://qross2/meshes/link1_v2.stl" scale="1.0 1.0 1.0"/>
			</geometry>
		</collision>
		<visual name="link1_v2:1_visual">
			<origin rpy="0.0 -0.0 0.0" xyz="-0.058249999999999955 0.01804999999999988 -0.18500000000000014"/>
			<geometry>
				<mesh filename="package://qross2/meshes/link1_v2.stl" scale="1.0 1.0 1.0"/>
			</geometry>
		</visual>
	</link>
	<link name="link2_v2:1">
		<inertial>
			<mass value="0.025261671356361627"/>
			<origin rpy="0 0 0" xyz="-0.006021692223729558 0.0008634074255883496 -0.008748991836740216"/>
			<inertia ixx="9.962831859746224e-06" ixy="1.0028626947655717e-08" ixz="-9.061502329466009e-09" iyy="4.892735585720232e-06" iyz="4.211437963393752e-07" izz="6.069447926677895e-06"/>
		</inertial>
		<collision name="link2_v2:1_collision">
			<origin rpy="0.0 -0.0 0.0" xyz="-0.15869950733609367 -9.99052000015166e-05 -0.18499999999999783"/>
			<geometry>
				<mesh filename="package://qross2/meshes/link2_v2.stl" scale="1.0 1.0 1.0"/>
			</geometry>
		</collision>
		<visual name="link2_v2:1_visual">
			<origin rpy="0.0 -0.0 0.0" xyz="-0.15869950733609367 -9.99052000015166e-05 -0.18499999999999783"/>
			<geometry>
				<mesh filename="package://qross2/meshes/link2_v2.stl" scale="1.0 1.0 1.0"/>
			</geometry>
		</visual>
	</link>
	<link name="link3_v2:1">
		<inertial>
			<mass value="0.15258541699707173"/>
			<origin rpy="0 0 0" xyz="1.3915515404028245e-05 0.01750032409451184 -0.02522251825012356"/>
			<inertia ixx="0.00020861295292856922" ixy="-1.1671366896059964e-09" ixz="5.8699406329765225e-08" iyy="0.00020565984768119349" iyz="-3.6005739727124064e-07" izz="2.4133734284270503e-05"/>
		</inertial>
		<collision name="link3_v2:1_collision">
			<origin rpy="0.0 -0.0 0.0" xyz="-0.1526995073360937 0.018064524350454015 -0.1597147299419067"/>
			<geometry>
				<mesh filename="package://qross2/meshes/link3_v2.stl" scale="1.0 1.0 1.0"/>
			</geometry>
		</collision>
		<visual name="link3_v2:1_visual">
			<origin rpy="0.0 -0.0 0.0" xyz="-0.1526995073360937 0.018064524350454015 -0.1597147299419067"/>
			<geometry>
				<mesh filename="package://qross2/meshes/link3_v2.stl" scale="1.0 1.0 1.0"/>
			</geometry>
		</visual>
	</link>
	<link name="link1_v2_(1):1">
		<inertial>
			<mass value="0.1666427112728253"/>
			<origin rpy="0 0 0" xyz="0.018328978492032147 -0.04564599663750806 -0.00877664503320022"/>
			<inertia ixx="8.861523122845796e-05" ixy="-1.1093582772710074e-06" ixz="-2.729272473079289e-07" iyy="4.58516502438826e-05" iyz="5.738366587259591e-06" izz="8.029824185391306e-05"/>
		</inertial>
		<collision name="link1_v2_(1):1_collision">
			<origin rpy="0.0 -0.0 0.0" xyz="0.018050000000000045 0.05825000000000007 -0.185"/>
			<geometry>
				<mesh filename="package://qross2/meshes/link1_v2_(1).stl" scale="1.0 1.0 1.0"/>
			</geometry>
		</collision>
		<visual name="link1_v2_(1):1_visual">
			<origin rpy="0.0 -0.0 0.0" xyz="0.018050000000000045 0.05825000000000007 -0.185"/>
			<geometry>
				<mesh filename="package://qross2/meshes/link1_v2_(1).stl" scale="1.0 1.0 1.0"/>
			</geometry>
		</visual>
	</link>
	<link name="link2_v2_(1):1">
		<inertial>
			<mass value="0.025261671356361634"/>
			<origin rpy="0 0 0" xyz="-0.0008634074255883733 -0.006021692223729502 -0.008748991836740161"/>
			<inertia ixx="4.892735585720054e-06" ixy="-1.0028626947637676e-08" ixz="-4.2114379633937384e-07" iyy="9.962831859746224e-06" iyz="-9.061502329554826e-09" izz="6.069447926677718e-06"/>
		</inertial>
		<collision name="link2_v2_(1):1_collision">
			<origin rpy="0.0 -0.0 0.0" xyz="-9.990520000124015e-05 0.14669950733609383 -0.18499999999999775"/>
			<geometry>
				<mesh filename="package://qross2/meshes/link2_v2_(1).stl" scale="1.0 1.0 1.0"/>
			</geometry>
		</collision>
		<visual name="link2_v2_(1):1_visual">
			<origin rpy="0.0 -0.0 0.0" xyz="-9.990520000124015e-05 0.14669950733609383 -0.18499999999999775"/>
			<geometry>
				<mesh filename="package://qross2/meshes/link2_v2_(1).stl" scale="1.0 1.0 1.0"/>
			</geometry>
		</visual>
	</link>
	<link name="link3_v2_(1):1">
		<inertial>
			<mass value="0.15258541699707173"/>
			<origin rpy="0 0 0" xyz="-0.01750032409451203 1.3915515404056e-05 -0.02522251825012345"/>
			<inertia ixx="0.00020565984768119492" ixy="1.1671366896198742e-09" ixz="3.6005739726989174e-07" iyy="0.00020861295292856993" iyz="5.869940632869941e-08" izz="2.4133734284269792e-05"/>
		</inertial>
		<collision name="link3_v2_(1):1_collision">
			<origin rpy="0.0 -0.0 0.0" xyz="-0.018264334750456752 0.1526995073360939 -0.15971472994190658"/>
			<geometry>
				<mesh filename="package://qross2/meshes/link3_v2_(1).stl" scale="1.0 1.0 1.0"/>
			</geometry>
		</collision>
		<visual name="link3_v2_(1):1_visual">
			<origin rpy="0.0 -0.0 0.0" xyz="-0.018264334750456752 0.1526995073360939 -0.15971472994190658"/>
			<geometry>
				<mesh filename="package://qross2/meshes/link3_v2_(1).stl" scale="1.0 1.0 1.0"/>
			</geometry>
		</visual>
	</link>
	<link name="link1_v2_(2):1">
		<inertial>
			<mass value="0.1666427112728253"/>
			<origin rpy="0 0 0" xyz="-0.04564599663750802 0.018328978492032206 0.008776645033200248"/>
			<inertia ixx="4.58516502438826e-05" ixy="-1.1093582772709483e-06" ixz="-5.738366587259947e-06" iyy="8.861523122845796e-05" iyz="2.729272473079372e-07" izz="8.029824185391341e-05"/>
		</inertial>
		<collision name="link1_v2_(2):1_collision">
			<origin rpy="0.0 -0.0 0.0" xyz="0.05825000000000014 0.018049999999999976 -0.185"/>
			<geometry>
				<mesh filename="package://qross2/meshes/link1_v2_(2).stl" scale="1.0 1.0 1.0"/>
			</geometry>
		</collision>
		<visual name="link1_v2_(2):1_visual">
			<origin rpy="0.0 -0.0 0.0" xyz="0.05825000000000014 0.018049999999999976 -0.185"/>
			<geometry>
				<mesh filename="package://qross2/meshes/link1_v2_(2).stl" scale="1.0 1.0 1.0"/>
			</geometry>
		</visual>
	</link>
	<link name="link2_v2_(2):1">
		<inertial>
			<mass value="0.025261671356361627"/>
			<origin rpy="0 0 0" xyz="0.00602169222372953 -0.0008634074255883384 -0.008748991836740216"/>
			<inertia ixx="9.962831859746312e-06" ixy="1.002862694767237e-08" ixz="9.061502329554826e-09" iyy="4.892735585720054e-06" iyz="-4.2114379633937453e-07" izz="6.069447926677718e-06"/>
		</inertial>
		<collision name="link2_v2_(2):1_collision">
			<origin rpy="0.0 -0.0 0.0" xyz="0.15869950733609386 -9.99052000014078e-05 -0.18500000000000227"/>
			<geometry>
				<mesh filename="package://qross2/meshes/link2_v2_(2).stl" scale="1.0 1.0 1.0"/>
			</geometry>
		</collision>
		<visual name="link2_v2_(2):1_visual">
			<origin rpy="0.0 -0.0 0.0" xyz="0.15869950733609386 -9.99052000014078e-05 -0.18500000000000227"/>
			<geometry>
				<mesh filename="package://qross2/meshes/link2_v2_(2).stl" scale="1.0 1.0 1.0"/>
			</geometry>
		</visual>
	</link>
	<link name="link3_v2_(2):1">
		<inertial>
			<mass value="0.15258541699707173"/>
			<origin rpy="0 0 0" xyz="-1.3915515403889467e-05 -0.017500324094511868 -0.025222518250123588"/>
			<inertia ixx="0.00020861295292856922" ixy="-1.1671366895948942e-09" ixz="-5.869940632869941e-08" iyy="0.00020565984768119422" iyz="3.6005739727103523e-07" izz="2.4133734284270503e-05"/>
		</inertial>
		<collision name="link3_v2_(2):1_collision">
			<origin rpy="0.0 -0.0 0.0" xyz="0.15269950733609391 -0.01826433475045693 -0.15971472994191113"/>
			<geometry>
				<mesh filename="package://qross2/meshes/link3_v2_(2).stl" scale="1.0 1.0 1.0"/>
			</geometry>
		</collision>
		<visual name="link3_v2_(2):1_visual">
			<origin rpy="0.0 -0.0 0.0" xyz="0.15269950733609391 -0.01826433475045693 -0.15971472994191113"/>
			<geometry>
				<mesh filename="package://qross2/meshes/link3_v2_(2).stl" scale="1.0 1.0 1.0"/>
			</geometry>
		</visual>
	</link>
	<link name="link1_v2_(3):1">
		<inertial>
			<mass value="0.1666427112728253"/>
			<origin rpy="0 0 0" xyz="0.01832897849203215 0.045645996637508075 0.008776645033200248"/>
			<inertia ixx="8.861523122845796e-05" ixy="1.1093582772710074e-06" ixz="2.7292724730793027e-07" iyy="4.58516502438826e-05" iyz="5.738366587259947e-06" izz="8.029824185391306e-05"/>
		</inertial>
		<collision name="link1_v2_(3):1_collision">
			<origin rpy="0.0 -0.0 0.0" xyz="0.01805000000000005 -0.058250000000000114 -0.18500000000000028"/>
			<geometry>
				<mesh filename="package://qross2/meshes/link1_v2_(3).stl" scale="1.0 1.0 1.0"/>
			</geometry>
		</collision>
		<visual name="link1_v2_(3):1_visual">
			<origin rpy="0.0 -0.0 0.0" xyz="0.01805000000000005 -0.058250000000000114 -0.18500000000000028"/>
			<geometry>
				<mesh filename="package://qross2/meshes/link1_v2_(3).stl" scale="1.0 1.0 1.0"/>
			</geometry>
		</visual>
	</link>
	<link name="link2_v2_(3):1">
		<inertial>
			<mass value="0.025350738519877708"/>
			<origin rpy="0 0 0" xyz="0.0009179463314236986 -0.005978383989634073 -0.008807090317583033"/>
			<inertia ixx="4.9191012707854755e-06" ixy="-9.99874061518996e-09" ixz="4.439265530407549e-07" iyy="1.0009548980591543e-05" iyz="9.029665414317378e-09" izz="6.091895376716039e-06"/>
		</inertial>
		<collision name="link2_v2_(3):1_collision">
			<origin rpy="0.0 -0.0 0.0" xyz="-9.99052000012035e-05 -0.15869950733609386 -0.18500000000000266"/>
			<geometry>
				<mesh filename="package://qross2/meshes/link2_v2_(3).stl" scale="1.0 1.0 1.0"/>
			</geometry>
		</collision>
		<visual name="link2_v2_(3):1_visual">
			<origin rpy="0.0 -0.0 0.0" xyz="-9.99052000012035e-05 -0.15869950733609386 -0.18500000000000266"/>
			<geometry>
				<mesh filename="package://qross2/meshes/link2_v2_(3).stl" scale="1.0 1.0 1.0"/>
			</geometry>
		</visual>
	</link>
	<link name="link3_v2_(3):1">
		<inertial>
			<mass value="0.15249634983355564"/>
			<origin rpy="0 0 0" xyz="0.017490365477258 -1.3923642911667367e-05 -0.02523724973818725"/>
			<inertia ixx="0.00020560105629790256" ixy="1.188281865016627e-09" ixz="-3.217307777822156e-07" iyy="0.0002085292878523866" iyz="-5.866812689703238e-08" izz="2.4106764626132815e-05"/>
		</inertial>
		<collision name="link3_v2_(3):1_collision">
			<origin rpy="0.0 -0.0 0.0" xyz="0.018064524350454275 -0.15269950733609355 -0.15971472994191147"/>
			<geometry>
				<mesh filename="package://qross2/meshes/link3_v2_(3).stl" scale="1.0 1.0 1.0"/>
			</geometry>
		</collision>
		<visual name="link3_v2_(3):1_visual">
			<origin rpy="0.0 -0.0 0.0" xyz="0.018064524350454275 -0.15269950733609355 -0.15971472994191147"/>
			<geometry>
				<mesh filename="package://qross2/meshes/link3_v2_(3).stl" scale="1.0 1.0 1.0"/>
			</geometry>
		</visual>
	</link>
	<joint name="rev0" type="continuous">
		<parent link="body:1"/>
		<child link="link1_v2:1"/>
		<origin rpy="0 0 0" xyz="0.058249999999999955 -0.01804999999999988 0.18500000000000014"/>
		<axis xyz="-3.81291588012573e-16 1.0 -1.02216230357419e-15"/>
	</joint>
	<joint name="rev1" type="continuous">
		<parent link="link1_v2:1"/>
		<child link="link2_v2:1"/>
		<origin rpy="0 0 0" xyz="0.10044950733609372 0.018149905200001395 -2.3037127760972e-15"/>
		<axis xyz="1.0 -1.5813722145894583e-15 7.846386362311605e-16"/>
	</joint>
	<joint name="rev2" type="continuous">
		<parent link="link2_v2:1"/>
		<child link="link3_v2:1"/>
		<origin rpy="0 0 0" xyz="-0.005999999999999978 -0.01816442955045553 -0.02528527005809114"/>
		<axis xyz="-2.7768666562080516e-15 -1.0 1.0792883280764027e-13"/>
	</joint>
	<joint name="rev3" type="continuous">
		<parent link="body:1"/>
		<child link="link1_v2_(1):1"/>
		<origin rpy="0 0 0" xyz="-0.018050000000000045 -0.05825000000000007 0.185"/>
		<axis xyz="1.0 -1.03783005397956e-15 4.35740640691421e-16"/>
	</joint>
	<joint name="rev4" type="continuous">
		<parent link="link1_v2_(1):1"/>
		<child link="link2_v2_(1):1"/>
		<origin rpy="0 0 0" xyz="0.018149905200001284 -0.08844950733609375 -2.248201624865942e-15"/>
		<axis xyz="-3.0004938565815924e-15 -1.0 8.458709761885262e-16"/>
	</joint>
	<joint name="rev5" type="continuous">
		<parent link="link2_v2_(1):1"/>
		<child link="link3_v2_(1):1"/>
		<origin rpy="0 0 0" xyz="0.018164429550455514 -0.006000000000000061 -0.02528527005809117"/>
		<axis xyz="1.0 -6.393853638772485e-15 1.0752231293303004e-13"/>
	</joint>
	<joint name="rev6" type="continuous">
		<parent link="body:1"/>
		<child link="link1_v2_(2):1"/>
		<origin rpy="0 0 0" xyz="-0.05825000000000014 -0.018049999999999976 0.185"/>
		<axis xyz="2.83776720881536e-16 1.0 1.7010322909832825e-17"/>
	</joint>
	<joint name="rev7" type="continuous">
		<parent link="link1_v2_(2):1"/>
		<child link="link2_v2_(2):1"/>
		<origin rpy="0 0 0" xyz="-0.10044950733609373 0.018149905200001384 2.275957200481571e-15"/>
		<axis xyz="-1.0 -1.6788870817204963e-15 -9.071033161458945e-16"/>
	</joint>
	<joint name="rev8" type="continuous">
		<parent link="link2_v2_(2):1"/>
		<child link="link3_v2_(2):1"/>
		<origin rpy="0 0 0" xyz="0.00599999999999995 0.01816442955045552 -0.02528527005809114"/>
		<axis xyz="-4.833926401020844e-16 1.0 1.0680121614706118e-13"/>
	</joint>
	<joint name="rev9" type="continuous">
		<parent link="body:1"/>
		<child link="link1_v2_(3):1"/>
		<origin rpy="0 0 0" xyz="-0.01805000000000005 0.058250000000000114 0.18500000000000028"/>
		<axis xyz="1.0 1.05385279987061e-15 -1.9440385535982498e-16"/>
	</joint>
	<joint name="rev10" type="continuous">
		<parent link="link1_v2_(3):1"/>
		<child link="link2_v2_(3):1"/>
		<origin rpy="0 0 0" xyz="0.018149905200001253 0.10044950733609376 2.3869795029440866e-15"/>
		<axis xyz="-3.0165166024726425e-15 1.0 -9.683356561032615e-16"/>
	</joint>
	<joint name="rev11" type="continuous">
		<parent link="link2_v2_(3):1"/>
		<child link="link3_v2_(3):1"/>
		<origin rpy="0 0 0" xyz="-0.01816442955045548 -0.006000000000000311 -0.025285270058091197"/>
		<axis xyz="-1.0 -5.640167279335791e-15 1.071585114677837e-13"/>
	</joint>
</robot>
